<?xml version="1.0" ?>
<robot name="turtlebot3_burger" xmlns:xacro="http://ros.org/wiki/xacro">
  <xacro:include filename="$(find koghf)/urdf/common_properties.xacro"/>
  <xacro:include filename="$(find koghf)/urdf/turtlebot3_burger.gazebo.xacro"/>

 <link name="base_footprint"/>

  <joint name="base_joint" type="fixed">
    <parent link="base_footprint"/>
    <child link="base_link"/>
    <origin xyz="0.0 0.0 0.0" rpy="0 0 0"/>
  </joint>

  <link name="base_link">
    <visual>
      <origin xyz="0 0 0.57" rpy="0 0 0"/>
      <geometry>
        <cylinder length="1" radius="0.20"/>
      </geometry>
    </visual>

    <collision>
      <origin xyz="0 0 0.57" rpy="0 0 0"/>
      <geometry>
        <cylinder length="1" radius="0.17"/>
      </geometry>
    </collision>

    <inertial>
      <origin xyz="0 0 0.57" rpy="0 0 0"/>
      <mass value="15"/>
      <inertia ixx=" 1.296667 " ixy="0" ixz="0"
               iyy=" 1.296667 " iyz="0"
               izz="0.3" />
    </inertial>
  </link>

  <joint name="wheel_left_joint" type="continuous">
    <parent link="base_link"/>
    <child link="wheel_left_link"/>
    <origin xyz="0.15 0.23 0.165" rpy="-1.57 0 0"/>
    <axis xyz="0 0 1"/>
  </joint>

  <link name="wheel_left_link">
    <visual>
      <origin xyz="0 0 0" rpy="1.57 0 0"/>
      <geometry>
        <mesh filename="package://koghf/meshes/wheels/left_tire.stl" scale="0.005 0.005 0.005"/>
      </geometry>
      <material name="dark"/>
    </visual>

    <collision>
      <origin xyz="0 0 0" rpy="0 0 0"/>
      <geometry>
        <cylinder length="0.09" radius="0.165"/>
      </geometry>
    </collision>

    <inertial>
      <origin xyz="0 0 0" />
      <mass value="2.5498940" />
      <inertia ixx="0.021321" ixy="0" ixz="0"
               iyy="0.021321" iyz="0"
               izz="0.038794 " />
      </inertial>
  </link>

  <joint name="wheel_right_joint" type="continuous">
    <parent link="base_link"/>
    <child link="wheel_right_link"/>
    <origin xyz="0.15 -0.23 0.165" rpy="-1.57 0 0"/>
    <axis xyz="0 0 1"/>
  </joint>

  <link name="wheel_right_link">
    <visual>
      <origin xyz="0 0 0" rpy="1.57 0 0"/>
      <geometry>
        <mesh filename="package://koghf/meshes/wheels/right_tire.stl" scale="0.005 0.005 0.005"/>
      </geometry>
      <material name="dark"/>
    </visual>

    <collision>
      <origin xyz="0 0 0" rpy="0 0 0"/>
      <geometry>
        <cylinder length="0.09" radius="0.165"/>
      </geometry>
    </collision>

    <inertial>
      <origin xyz="0 0 0" />
      <mass value="2.5498940" />
      <inertia ixx="0.021321" ixy="0" ixz="0"
               iyy="0.021321" iyz="0"
               izz="0.038794" />
      </inertial>
  </link>

  <joint name="caster_back_joint" type="fixed">
    <parent link="base_link"/>
    <child link="caster_back_link"/>
    <origin xyz="-0.22 0 0.022" rpy="-1.57 0 0"/>
  </joint>

  <link name="caster_back_link">
  
    <visual>
      <origin xyz="0 0 0" rpy="0 0 1.57"/>
      <geometry>
        <sphere radius="0.02"/>
      </geometry>
    </visual>
    
    <collision>
      <origin xyz="0 0 0" rpy="0 0 0"/>
      <geometry>
      <sphere radius="0.02"/>
      </geometry>
    </collision>

    <inertial>
      <origin xyz="0 0 0" />
      <mass value="0.005" />
      <inertia ixx="0.001" ixy="0.0" ixz="0.0"
               iyy="0.001" iyz="0.0"
               izz="0.001" />
    </inertial>
  </link>

  <joint name="imu_joint" type="fixed">
    <parent link="base_link"/>
    <child link="imu_link"/>
    <origin xyz="-0.032 0 0.068" rpy="0 0 0"/>
  </joint>

  <link name="imu_link"/>

  <joint name="scan_joint" type="fixed">
    <parent link="base_link"/>
    <child link="base_scan"/>
    <origin xyz="-0.032 0 0.172" rpy="0 0 0"/>
  </joint>

  <link name="base_scan">
    <visual>
      <origin xyz="0 0 0.0" rpy="0 0 0"/>
      <geometry>
        <mesh filename="package://koghf/meshes/sensors/lds.stl" scale="0.001 0.001 0.001"/>
      </geometry>
      <material name="dark"/>
    </visual>

    <collision>
      <origin xyz="0.015 0 -0.0065" rpy="0 0 0"/>
      <geometry>
        <cylinder length="0.0315" radius="0.055"/>
      </geometry>
    </collision>

    <inertial>
      <mass value="0.114" />
      <origin xyz="0 0 0" />
      <inertia ixx="0.001" ixy="0.0" ixz="0.0"
               iyy="0.001" iyz="0.0"
               izz="0.001" />
    </inertial>
  </link>

  <!-- Camera -->
  <joint type="continuous" name="camera_joint">
    <origin xyz="0 0 1.08" rpy="0 -1.5708 0"/>
    <child link="camera_link"/>
    <parent link="base_link"/>
    <axis xyz="0 1 0" />
  </joint>

  <link name='camera_link'>
    <pose>0 0 0 0 0 0</pose>
    <inertial>
      <mass value="0.001"/>
      <origin xyz="0 0 0" rpy="0 0 0"/>
      <inertia
          ixx="1e-6" ixy="0" ixz="0"
          iyy="1e-6" iyz="0"
          izz="1e-6"
      />
    </inertial>

    <collision name='collision'>
      <origin xyz="0 0 0" rpy="0 0 0"/> 
      <geometry>
        <box size=".02 .02 .02"/>
      </geometry>
    </collision>

    <visual name='camera_link_visual'>
      <origin xyz="0 0 0" rpy="0 0 0"/>
      <geometry>
        <box size=".02 .02 .02"/>
      </geometry>
    </visual>

  </link>

  <gazebo reference="camera_link">
    <material>Gazebo/Red</material>
  </gazebo>
   <gazebo reference="caster_back_link">
    <material>Gazebo/Grey</material>
  </gazebo>

  <joint type="fixed" name="camera_optical_joint">
    <origin xyz="0 0 0" rpy="-1.5707 0 -1.5707"/>
    <child link="camera_link_optical"/>
    <parent link="camera_link"/>
  </joint>

  <link name="camera_link_optical">
  </link>


 <!-- Tray -->
  <joint type="fixed" name="tray_joint">
    <origin xyz="0 0 1.075" rpy="0 0 -1.5708"/>
    <child link="tray_link"/>
    <parent link="base_link"/>
    <axis xyz="0 1 0" />
  </joint>

  <link name='tray_link'>
    <pose>0 0 0 0 0 0</pose>
    <visual>
      <origin xyz="0 0 0" rpy="0 0 0"/>
      <geometry>
        <mesh filename="package://koghf/meshes/coffee_tray.stl" scale="0.013 0.016 0.013"/>
      </geometry>
    </visual>
    <visual>
      <origin xyz="0 0 0" rpy="0 0 0"/>
      <geometry>
        <box size=".39 .38 .007" />
      </geometry>
    </visual>
    <inertial>
      <mass value="0.01"/>
      <origin xyz="0 0 0" rpy="0 0 0"/>
      <inertia
          ixx="1e-6" ixy="0" ixz="0"
          iyy="1e-6" iyz="0"
          izz="1e-6"
      />
    </inertial>

    

  </link>

</robot>
